<?xml version='1.0' encoding='utf-8'?>
<robot name="ur10e_robotiq_2f140">
  <link name="world" />
  <link name="base_link" />
  <link name="base_link_inertia">
    <visual>
      <origin rpy="0 0 3.141592653589793" xyz="0 0 0" />
      <geometry>
        <mesh filename="package://ur_description/meshes/ur10e/visual/base.dae" />
      </geometry>
    </visual>
    <collision>
      <origin rpy="0 0 3.141592653589793" xyz="0 0 0" />
      <geometry>
        <mesh filename="package://ur_description/meshes/ur10e/collision/base.stl" />
      </geometry>
    </collision>
    <inertial>
      <mass value="4.0" />
      <origin rpy="0 0 0" xyz="0 0 0" />
      <inertia ixx="0.0061063308908" ixy="0.0" ixz="0.0" iyy="0.0061063308908" iyz="0.0" izz="0.01125" />
    </inertial>
  </link>
  <link name="shoulder_link">
    <visual>
      <origin rpy="0 0 3.141592653589793" xyz="0 0 0" />
      <geometry>
        <mesh filename="package://ur_description/meshes/ur10e/visual/shoulder.dae" />
      </geometry>
    </visual>
    <collision>
      <origin rpy="0 0 3.141592653589793" xyz="0 0 0" />
      <geometry>
        <mesh filename="package://ur_description/meshes/ur10e/collision/shoulder.stl" />
      </geometry>
    </collision>
    <inertial>
      <mass value="7.369" />
      <origin rpy="1.570796326794897 0 0" xyz="0.021 -0.027 0.0" />
      <inertia ixx="0.03408" ixy="2e-05" ixz="-0.00425" iyy="0.03529" iyz="8e-05" izz="0.02156" />
    </inertial>
  </link>
  <link name="upper_arm_link">
    <visual>
      <origin rpy="1.5707963267948966 0 -1.5707963267948966" xyz="0 0 0.1762" />
      <geometry>
        <mesh filename="package://ur_description/meshes/ur10e/visual/upperarm.dae" />
      </geometry>
    </visual>
    <collision>
      <origin rpy="1.5707963267948966 0 -1.5707963267948966" xyz="0 0 0.1762" />
      <geometry>
        <mesh filename="package://ur_description/meshes/ur10e/collision/upperarm.stl" />
      </geometry>
    </collision>
    <inertial>
      <mass value="13.051" />
      <origin rpy="0 0 0" xyz="-0.2327 0.0 0.158" />
      <inertia ixx="0.02814" ixy="5e-05" ixz="-0.01561" iyy="0.77068" iyz="2e-05" izz="0.76943" />
    </inertial>
  </link>
  <link name="forearm_link">
    <visual>
      <origin rpy="1.5707963267948966 0 -1.5707963267948966" xyz="0 0 0.0393" />
      <geometry>
        <mesh filename="package://ur_description/meshes/ur10e/visual/forearm.dae" />
      </geometry>
    </visual>
    <collision>
      <origin rpy="1.5707963267948966 0 -1.5707963267948966" xyz="0 0 0.0393" />
      <geometry>
        <mesh filename="package://ur_description/meshes/ur10e/collision/forearm.stl" />
      </geometry>
    </collision>
    <inertial>
      <mass value="3.989" />
      <origin rpy="0 0 0" xyz="-0.33155 0.0 0.068" />
      <inertia ixx="0.01014" ixy="8e-05" ixz="0.00916" iyy="0.30928" iyz="0.0" izz="0.30646" />
    </inertial>
  </link>
  <link name="wrist_1_link">
    <visual>
      <origin rpy="1.5707963267948966 0 0" xyz="0 0 -0.135" />
      <geometry>
        <mesh filename="package://ur_description/meshes/ur10e/visual/wrist1.dae" />
      </geometry>
    </visual>
    <collision>
      <origin rpy="1.5707963267948966 0 0" xyz="0 0 -0.135" />
      <geometry>
        <mesh filename="package://ur_description/meshes/ur10e/collision/wrist1.stl" />
      </geometry>
    </collision>
    <inertial>
      <mass value="2.1" />
      <origin rpy="1.570796326794897 0 0" xyz="0.0 -0.018 0.007" />
      <inertia ixx="0.00296" ixy="-1e-05" ixz="0.0" iyy="0.00222" iyz="-0.00024" izz="0.00258" />
    </inertial>
  </link>
  <link name="wrist_2_link">
    <visual>
      <origin rpy="0 0 0" xyz="0 0 -0.12" />
      <geometry>
        <mesh filename="package://ur_description/meshes/ur10e/visual/wrist2.dae" />
      </geometry>
    </visual>
    <collision>
      <origin rpy="0 0 0" xyz="0 0 -0.12" />
      <geometry>
        <mesh filename="package://ur_description/meshes/ur10e/collision/wrist2.stl" />
      </geometry>
    </collision>
    <inertial>
      <mass value="1.98" />
      <origin rpy="-1.570796326794897 0 0" xyz="0.0 0.018 -0.007" />
      <inertia ixx="0.00296" ixy="-1e-05" ixz="0.0" iyy="0.00222" iyz="-0.00024" izz="0.00258" />
    </inertial>
  </link>
  <link name="wrist_3_link">
    <visual>
      <origin rpy="1.5707963267948966 0 0" xyz="0 -0.0005 -0.1168" />
      <geometry>
        <mesh filename="package://ur_description/meshes/ur10e/visual/wrist3.dae" />
      </geometry>
    </visual>
    <collision>
      <origin rpy="1.5707963267948966 0 0" xyz="0 -0.0005 -0.1168" />
      <geometry>
        <mesh filename="package://ur_description/meshes/ur10e/collision/wrist3.stl" />
      </geometry>
    </collision>
    <inertial>
      <mass value="0.615" />
      <origin rpy="0 0 0" xyz="0.0 0.0 -0.026" />
      <inertia ixx="0.0004" ixy="0.0" ixz="0.0" iyy="0.00041" iyz="0.0" izz="0.00034" />
    </inertial>
  </link>
  <joint name="base_joint" type="fixed">
    <origin rpy="0 0 0" xyz="0 0 0" />
    <parent link="world" />
    <child link="base_link" />
  </joint>
  <joint name="base_link-base_link_inertia" type="fixed">
    <parent link="base_link" />
    <child link="base_link_inertia" />
    <origin rpy="0 0 3.141592653589793" xyz="0 0 0" />
  </joint>
  <joint name="shoulder_pan_joint" type="revolute">
    <parent link="base_link_inertia" />
    <child link="shoulder_link" />
    <origin rpy="0 0 0" xyz="0 0 0.1807" />
    <axis xyz="0 0 1" />
    <limit effort="330.0" lower="-6.283185307179586" upper="6.283185307179586" velocity="2.0943951023931953" />
    <dynamics damping="0" friction="0" />
  </joint>
  <joint name="shoulder_lift_joint" type="revolute">
    <parent link="shoulder_link" />
    <child link="upper_arm_link" />
    <origin rpy="1.570796327 0 0" xyz="0 0 0" />
    <axis xyz="0 0 1" />
    <limit effort="330.0" lower="-6.283185307179586" upper="6.283185307179586" velocity="2.0943951023931953" />
    <dynamics damping="0" friction="0" />
  </joint>
  <joint name="elbow_joint" type="revolute">
    <parent link="upper_arm_link" />
    <child link="forearm_link" />
    <origin rpy="0 0 0" xyz="-0.6127 0 0" />
    <axis xyz="0 0 1" />
    <limit effort="150.0" lower="-3.141592653589793" upper="3.141592653589793" velocity="3.141592653589793" />
    <dynamics damping="0" friction="0" />
  </joint>
  <joint name="wrist_1_joint" type="revolute">
    <parent link="forearm_link" />
    <child link="wrist_1_link" />
    <origin rpy="0 0 0" xyz="-0.57155 0 0.17415" />
    <axis xyz="0 0 1" />
    <limit effort="54.0" lower="-6.283185307179586" upper="6.283185307179586" velocity="3.141592653589793" />
    <dynamics damping="0" friction="0" />
  </joint>
  <joint name="wrist_2_joint" type="revolute">
    <parent link="wrist_1_link" />
    <child link="wrist_2_link" />
    <origin rpy="1.570796327 0 0" xyz="0 -0.11985 -2.458164590756244e-11" />
    <axis xyz="0 0 1" />
    <limit effort="54.0" lower="-6.283185307179586" upper="6.283185307179586" velocity="3.141592653589793" />
    <dynamics damping="0" friction="0" />
  </joint>
  <joint name="wrist_3_joint" type="revolute">
    <parent link="wrist_2_link" />
    <child link="wrist_3_link" />
    <origin rpy="1.570796326589793 3.141592653589793 3.141592653589793" xyz="0 0.11655 -2.390480459346185e-11" />
    <axis xyz="0 0 1" />
    <limit effort="54.0" lower="-6.283185307179586" upper="6.283185307179586" velocity="3.141592653589793" />
    <dynamics damping="0" friction="0" />
  </joint>
  <link name="ft_frame" />
  <joint name="wrist_3_link-ft_frame" type="fixed">
    <parent link="wrist_3_link" />
    <child link="ft_frame" />
    <origin rpy="3.141592653589793 0 0" xyz="0 0 0" />
  </joint>
  <link name="base" />
  <joint name="base_link-base_fixed_joint" type="fixed">
    <origin rpy="0 0 3.141592653589793" xyz="0 0 0" />
    <parent link="base_link" />
    <child link="base" />
  </joint>
  <link name="flange" />
  <joint name="wrist_3-flange" type="fixed">
    <parent link="wrist_3_link" />
    <child link="flange" />
    <origin rpy="0 -1.5707963267948966 -1.5707963267948966" xyz="0 0 0" />
  </joint>
  <link name="tool0" />
  <joint name="flange-tool0" type="fixed">
    <origin rpy="1.5707963267948966 0 1.5707963267948966" xyz="0 0 0" />
    <parent link="flange" />
    <child link="tool0" />
  </joint>
  <link name="robotiq_base_link">
    <inertial>
      <origin rpy="0 0 0" xyz="8.625E-08 -4.6583E-06 0.03145" />
      <mass value="0.22652" />
      <inertia ixx="0.00020005" ixy="-4.2442E-10" ixz="-2.9069E-10" iyy="0.00017832" iyz="-3.4402E-08" izz="0.00013478" />
    </inertial>
    <visual>
      <origin rpy="0 0 0" xyz="0 0 0" />
      <geometry>
        <mesh filename="package://pal_robotiq_description/meshes/visual/robotiq_base_link.stl" />
      </geometry>
      <material name="">
        <color rgba="0.1 0.1 0.1 1" />
      </material>
    </visual>
    <collision>
      <origin rpy="0 0 0" xyz="0 0 0" />
      <geometry>
        <mesh filename="package://pal_robotiq_description/meshes/collision/robotiq_base_link.stl" />
      </geometry>
    </collision>
  </link>
  <gazebo reference="robotiq_base_link">
    <material>Gazebo/DarkGrey</material>
  </gazebo>
  <joint name="robotiq_grasping_frame_joint" type="fixed">
    <parent link="robotiq_base_link" />
    <child link="robotiq_grasping_frame" />
    <origin rpy="0 -1.5708 0" xyz="0 0 0.14" />
  </joint>
  <link name="robotiq_grasping_frame" />
  <joint name="robotiq_grasping_frame_Y_joint" type="fixed">
    <parent link="robotiq_base_link" />
    <child link="robotiq_grasping_frame_Y" />
    <origin rpy="1.5708 0 0" xyz="0 0 0.14" />
  </joint>
  <link name="robotiq_grasping_frame_Y" />
  <joint name="robotiq_grasping_frame_Z_joint" type="fixed">
    <parent link="robotiq_base_link" />
    <child link="robotiq_grasping_frame_Z" />
    <origin rpy="0 0 0" xyz="0 0 0.14" />
  </joint>
  <link name="robotiq_grasping_frame_Z" />
  <link name="robotiq_coupler_link">
    <visual>
      <origin rpy="3.1416 0 0" xyz="0 0 0.0" />
      <geometry>
        <mesh filename="package://pal_robotiq_description/meshes/visual/pal_robotiq_coupling.stl" />
      </geometry>
      <material name="">
        <color rgba="0 0 0 1" />
      </material>
    </visual>
    <collision>
      <origin rpy="3.1416 0 0" xyz="0 0 0.0" />
      <geometry>
        <mesh filename="package://pal_robotiq_description/meshes/visual/pal_robotiq_coupling.stl" />
      </geometry>
    </collision>
    <inertial>
      <mass value="0.2" />
      <origin xyz="0.0 0.0 -0.01" />
      <inertia ixx="0.000001" ixy="0.000000" ixz="0.000000" iyx="0.000000" iyy="0.000001" iyz="0.000000" izx="0.000000" izy="0.000000" izz="0.000001" />
    </inertial>
  </link>
  <gazebo reference="robotiq_coupler_link">
    <material>Gazebo/DarkGrey</material>
  </gazebo>
  <link name="robotiq_left_outer_knuckle">
    <inertial>
      <origin rpy="0 0 0" xyz="-0.000200000000003065 0.0199435877845359 0.0292245259211331" />
      <mass value="0.00853198276973456" />
      <inertia ixx="2.89328108496468E-06" ixy="-1.57935047237397E-19" ixz="-1.93980378593255E-19" iyy="1.86719750325683E-06" iyz="-1.21858577871576E-06" izz="1.21905238907251E-06" />
    </inertial>
    <visual>
      <origin rpy="0 0 0" xyz="0 0 0" />
      <geometry>
        <mesh filename="package://pal_robotiq_description/meshes/visual/robotiq_140_outer_knuckle.stl" />
      </geometry>
      <material name="">
        <color rgba="0.792156862745098 0.819607843137255 0.933333333333333 1" />
      </material>
    </visual>
    <collision>
      <origin rpy="0 0 0" xyz="0 0 0" />
      <geometry>
        <mesh filename="package://pal_robotiq_description/meshes/collision/robotiq_140_outer_knuckle.stl" />
      </geometry>
    </collision>
  </link>
  <link name="robotiq_left_outer_finger">
    <inertial>
      <origin rpy="0 0 0" xyz="0.00030115855001899 0.0373907951953854 -0.0208027427000385" />
      <mass value="0.022614240507152" />
      <inertia ixx="1.52518312458174E-05" ixy="9.76583423954399E-10" ixz="-5.43838577022588E-10" iyy="6.17694243867776E-06" iyz="6.78636130740228E-06" izz="1.16494917907219E-05" />
    </inertial>
    <visual>
      <origin rpy="0 0 0" xyz="0 0 0" />
      <geometry>
        <mesh filename="package://pal_robotiq_description/meshes/visual/robotiq_140_outer_finger.stl" />
      </geometry>
      <material name="">
        <color rgba="0.1 0.1 0.1 1" />
      </material>
    </visual>
    <collision>
      <origin rpy="0 0 0" xyz="0 0 0" />
      <geometry>
        <mesh filename="package://pal_robotiq_description/meshes/collision/robotiq_140_outer_finger.stl" />
      </geometry>
    </collision>
  </link>
  <gazebo reference="robotiq_left_outer_finger">
    <material>Gazebo/DarkGrey</material>
  </gazebo>
  <link name="robotiq_left_inner_finger">
    <inertial>
      <origin rpy="0 0 0" xyz="0.000299999999999317 0.0160078233491243 -0.0136945669206257" />
      <mass value="0.0104003125914103" />
      <inertia ixx="2.71909453810972E-06" ixy="1.35402465472579E-21" ixz="-7.1817349065269E-22" iyy="7.69100314106116E-07" iyz="6.74715432769696E-07" izz="2.30315190420171E-06" />
    </inertial>
    <visual>
      <origin rpy="0 0 0" xyz="0 0 0" />
      <geometry>
        <mesh filename="package://pal_robotiq_description/meshes/visual/robotiq_140_inner_finger.stl" />
      </geometry>
      <material name="">
        <color rgba="0.1 0.1 0.1 1" />
      </material>
    </visual>
    <collision>
      <origin rpy="0 0 0" xyz="0 0 0" />
      <geometry>
        <mesh filename="package://pal_robotiq_description/meshes/collision/robotiq_140_inner_finger.stl" />
      </geometry>
    </collision>
  </link>
  <gazebo reference="robotiq_left_inner_finger">
    <collision name="robotiq_left_inner_finger">
      <surface>
        <friction>
          <torsional>
            <coefficient>1000.0</coefficient>
            <use_patch_radius>true</use_patch_radius>
            <patch_radius>0.1</patch_radius>
          </torsional>
        </friction>
        <contact>
          <poissons_ratio>1.0</poissons_ratio>
          <elastic_modulus>Inf</elastic_modulus>
        </contact>
      </surface>
    </collision>
    <mu1>Inf</mu1>
    <mu2>Inf</mu2>
    <maxVel>0.0</maxVel>
    <kp>Inf</kp>
    <kd>100.0</kd>
    <fdir1>1 0 0</fdir1>
    <maxVel>0.0</maxVel>
    <minDepth>0.01</minDepth>
    <maxContacts>10</maxContacts>
    <material>Gazebo/DarkGrey</material>
  </gazebo>
  <link name="robotiq_left_inner_finger_pad">
    <visual>
      <origin rpy="0 0 0" xyz="0 0 0" />
      <geometry>
        <box size="0.027 0.065 0.0075" />
      </geometry>
      <material name="">
        <color rgba="0.9 0.9 0.9 1" />
      </material>
    </visual>
    <collision>
      <origin rpy="0 0 0" xyz="0 0 0" />
      <geometry>
        <box size="0.03 0.07 0.0075" />
      </geometry>
      <material name="">
        <color rgba="0.9 0.0 0.0 1" />
      </material>
    </collision>
  </link>
  <link name="robotiq_left_inner_knuckle">
    <inertial>
      <origin rpy="0 0 0" xyz="0.000123011831763771 0.0507850843201817 0.00103968640075166" />
      <mass value="0.0271177346495152" />
      <inertia ixx="2.61910379223783E-05" ixy="-2.43616858946494E-07" ixz="-6.37789906117123E-09" iyy="2.8270243746167E-06" iyz="-5.37200748039765E-07" izz="2.83695868220296E-05" />
    </inertial>
    <visual>
      <origin rpy="0 0 0" xyz="0 0 0" />
      <geometry>
        <mesh filename="package://pal_robotiq_description/meshes/visual/robotiq_140_inner_knuckle.stl" />
      </geometry>
      <material name="">
        <color rgba="0.1 0.1 0.1 1" />
      </material>
    </visual>
    <collision>
      <origin rpy="0 0 0" xyz="0 0 0" />
      <geometry>
        <mesh filename="package://pal_robotiq_description/meshes/collision/robotiq_140_inner_knuckle.stl" />
      </geometry>
    </collision>
  </link>
  <gazebo reference="robotiq_left_inner_knuckle">
    <kp>1000000.0</kp>
    <kd>100.0</kd>
    <mu1>Inf</mu1>
    <mu2>Inf</mu2>
    <fdir1>0 0 0</fdir1>
    <maxVel>0.0</maxVel>
    <minDepth>0.01</minDepth>
    <material>Gazebo/DarkGrey</material>
  </gazebo>
  <link name="robotiq_right_outer_knuckle">
    <inertial>
      <origin rpy="0 0 0" xyz="-0.000200000000003065 0.0199435877845359 0.0292245259211331" />
      <mass value="0.00853198276973456" />
      <inertia ixx="2.89328108496468E-06" ixy="-1.57935047237397E-19" ixz="-1.93980378593255E-19" iyy="1.86719750325683E-06" iyz="-1.21858577871576E-06" izz="1.21905238907251E-06" />
    </inertial>
    <visual>
      <origin rpy="0 0 0" xyz="0 0 0" />
      <geometry>
        <mesh filename="package://pal_robotiq_description/meshes/visual/robotiq_140_outer_knuckle.stl" />
      </geometry>
      <material name="">
        <color rgba="0.792156862745098 0.819607843137255 0.933333333333333 1" />
      </material>
    </visual>
    <collision>
      <origin rpy="0 0 0" xyz="0 0 0" />
      <geometry>
        <mesh filename="package://pal_robotiq_description/meshes/collision/robotiq_140_outer_knuckle.stl" />
      </geometry>
    </collision>
  </link>
  <link name="robotiq_right_outer_finger">
    <inertial>
      <origin rpy="0 0 0" xyz="0.00030115855001899 0.0373907951953854 -0.0208027427000385" />
      <mass value="0.022614240507152" />
      <inertia ixx="1.52518312458174E-05" ixy="9.76583423954399E-10" ixz="-5.43838577022588E-10" iyy="6.17694243867776E-06" iyz="6.78636130740228E-06" izz="1.16494917907219E-05" />
    </inertial>
    <visual>
      <origin rpy="0 0 0" xyz="0 0 0" />
      <geometry>
        <mesh filename="package://pal_robotiq_description/meshes/visual/robotiq_140_outer_finger.stl" />
      </geometry>
      <material name="">
        <color rgba="0.1 0.1 0.1 1" />
      </material>
    </visual>
    <collision>
      <origin rpy="0 0 0" xyz="0 0 0" />
      <geometry>
        <mesh filename="package://pal_robotiq_description/meshes/collision/robotiq_140_outer_finger.stl" />
      </geometry>
    </collision>
  </link>
  <gazebo reference="robotiq_right_outer_finger">
    <material>Gazebo/DarkGrey</material>
  </gazebo>
  <link name="robotiq_right_inner_finger">
    <inertial>
      <origin rpy="0 0 0" xyz="0.000299999999999317 0.0160078233491243 -0.0136945669206257" />
      <mass value="0.0104003125914103" />
      <inertia ixx="2.71909453810972E-06" ixy="1.35402465472579E-21" ixz="-7.1817349065269E-22" iyy="7.69100314106116E-07" iyz="6.74715432769696E-07" izz="2.30315190420171E-06" />
    </inertial>
    <visual>
      <origin rpy="0 0 0" xyz="0 0 0" />
      <geometry>
        <mesh filename="package://pal_robotiq_description/meshes/visual/robotiq_140_inner_finger.stl" />
      </geometry>
      <material name="">
        <color rgba="0.1 0.1 0.1 1" />
      </material>
    </visual>
    <collision>
      <origin rpy="0 0 0" xyz="0 0 0" />
      <geometry>
        <mesh filename="package://pal_robotiq_description/meshes/collision/robotiq_140_inner_finger.stl" />
      </geometry>
    </collision>
  </link>
  <gazebo reference="robotiq_right_inner_finger">
    <collision name="robotiq_right_inner_finger">
      <surface>
        <friction>
          <torsional>
            <coefficient>1000.0</coefficient>
            <use_patch_radius>true</use_patch_radius>
            <patch_radius>0.1</patch_radius>
          </torsional>
        </friction>
        <contact>
          <poissons_ratio>1.0</poissons_ratio>
          <elastic_modulus>Inf</elastic_modulus>
        </contact>
      </surface>
    </collision>
    <mu1>Inf</mu1>
    <mu2>Inf</mu2>
    <maxVel>0.0</maxVel>
    <kp>Inf</kp>
    <kd>100.0</kd>
    <fdir1>1 0 0</fdir1>
    <maxVel>0.0</maxVel>
    <minDepth>0.01</minDepth>
    <maxContacts>10</maxContacts>
    <material>Gazebo/DarkGrey</material>
  </gazebo>
  <link name="robotiq_right_inner_finger_pad">
    <visual>
      <origin rpy="0 0 0" xyz="0 0 0" />
      <geometry>
        <box size="0.027 0.065 0.0075" />
      </geometry>
      <material name="">
        <color rgba="0.9 0.9 0.9 1" />
      </material>
    </visual>
    <collision>
      <origin rpy="0 0 0" xyz="0 0 0" />
      <geometry>
        <box size="0.03 0.07 0.0075" />
      </geometry>
      <material name="">
        <color rgba="0.9 0.0 0.0 1" />
      </material>
    </collision>
  </link>
  <link name="robotiq_right_inner_knuckle">
    <inertial>
      <origin rpy="0 0 0" xyz="0.000123011831763771 0.0507850843201817 0.00103968640075166" />
      <mass value="0.0271177346495152" />
      <inertia ixx="2.61910379223783E-05" ixy="-2.43616858946494E-07" ixz="-6.37789906117123E-09" iyy="2.8270243746167E-06" iyz="-5.37200748039765E-07" izz="2.83695868220296E-05" />
    </inertial>
    <visual>
      <origin rpy="0 0 0" xyz="0 0 0" />
      <geometry>
        <mesh filename="package://pal_robotiq_description/meshes/visual/robotiq_140_inner_knuckle.stl" />
      </geometry>
      <material name="">
        <color rgba="0.1 0.1 0.1 1" />
      </material>
    </visual>
    <collision>
      <origin rpy="0 0 0" xyz="0 0 0" />
      <geometry>
        <mesh filename="package://pal_robotiq_description/meshes/collision/robotiq_140_inner_knuckle.stl" />
      </geometry>
    </collision>
  </link>
  <gazebo reference="robotiq_right_inner_knuckle">
    <kp>1000000.0</kp>
    <kd>100.0</kd>
    <mu1>Inf</mu1>
    <mu2>Inf</mu2>
    <fdir1>0 0 0</fdir1>
    <maxVel>0.0</maxVel>
    <minDepth>0.01</minDepth>
    <material>Gazebo/DarkGrey</material>
  </gazebo>
  <joint name="robotiq_base_joint" type="fixed">
    <parent link="robotiq_coupler_link" />
    <child link="robotiq_base_link" />
    <origin rpy="0 0 0" xyz="0 0 0.03154" />
  </joint>
  <joint name="robotiq_coupler_joint" type="fixed">
    <parent link="tool0" />
    <child link="robotiq_coupler_link" />
    <origin rpy="0 0 1.57079632679" xyz="0 0 0" />
  </joint>
  <joint name="robotiq_finger_joint" type="revolute">
    <origin rpy="2.2957963267948966 0 0" xyz="0 -0.030601 0.054905" />
    <parent link="robotiq_base_link" />
    <child link="robotiq_left_outer_knuckle" />
    <axis xyz="-1 0 0" />
    <limit effort="0.12" lower="0.0" upper="0.7" velocity="2" />
    <dynamics damping="0.03" />
    <safety_controller k_position="20" k_velocity="20" soft_lower_limit="0.001" soft_upper_limit="0.699" />
  </joint>
  <gazebo reference="robotiq_finger_joint">
    <implicitSpringDamper>1</implicitSpringDamper>
    <provideFeedback>1</provideFeedback>
  </gazebo>
  <joint name="robotiq_left_outer_finger_joint" type="fixed">
    <origin rpy="0 0 0" xyz="0 0.01821998610742 0.0260018192872234" />
    <parent link="robotiq_left_outer_knuckle" />
    <child link="robotiq_left_outer_finger" />
    <axis xyz="1 0 0" />
  </joint>
  <joint name="robotiq_left_inner_knuckle_joint" type="revolute">
    <origin rpy="2.2957963267948966 0 0.0" xyz="0 -0.0127 0.06142" />
    <parent link="robotiq_base_link" />
    <child link="robotiq_left_inner_knuckle" />
    <axis xyz="1 0 0" />
    <limit effort="0.12" lower="-0.8757" upper="0.8757" velocity="2" />
    <mimic joint="robotiq_finger_joint" multiplier="-1" offset="0" />
  </joint>
  <joint name="robotiq_left_inner_finger_joint" type="revolute">
    <origin rpy="-0.725 0 0" xyz="0 0.0817554015893473 -0.0282203446692936" />
    <parent link="robotiq_left_outer_finger" />
    <child link="robotiq_left_inner_finger" />
    <axis xyz="1 0 0" />
    <limit effort="0.12" lower="-0.8757" upper="0.8757" velocity="2" />
    <mimic joint="robotiq_finger_joint" multiplier="1" offset="0" />
  </joint>
  <joint name="robotiq_left_inner_finger_pad_joint" type="fixed">
    <origin rpy="0 0 0" xyz="0 0.0457554015893473 -0.0272203446692936" />
    <parent link="robotiq_left_inner_finger" />
    <child link="robotiq_left_inner_finger_pad" />
    <axis xyz="0 0 1" />
  </joint>
  <joint name="robotiq_right_outer_knuckle_joint" type="revolute">
    <origin rpy="2.2957963267948966 0 3.141592653589793" xyz="0 0.030601 0.054905" />
    <parent link="robotiq_base_link" />
    <child link="robotiq_right_outer_knuckle" />
    <axis xyz="1 0 0" />
    <limit effort="0.12" lower="-0.725" upper="0.725" velocity="2" />
    <mimic joint="robotiq_finger_joint" multiplier="-1" offset="0" />
  </joint>
  <joint name="robotiq_right_outer_finger_joint" type="fixed">
    <origin rpy="0 0 0" xyz="0 0.01821998610742 0.0260018192872234" />
    <parent link="robotiq_right_outer_knuckle" />
    <child link="robotiq_right_outer_finger" />
    <axis xyz="1 0 0" />
  </joint>
  <joint name="robotiq_right_inner_knuckle_joint" type="revolute">
    <origin rpy="2.2957963267948966 0 -3.141592653589793" xyz="0 0.0127 0.06142" />
    <parent link="robotiq_base_link" />
    <child link="robotiq_right_inner_knuckle" />
    <axis xyz="1 0 0" />
    <limit effort="0.12" lower="-0.8757" upper="0.8757" velocity="2" />
    <mimic joint="robotiq_finger_joint" multiplier="-1" offset="0" />
  </joint>
  <joint name="robotiq_right_inner_finger_joint" type="revolute">
    <origin rpy="-0.725 0 0" xyz="0 0.0817554015893473 -0.0282203446692936" />
    <parent link="robotiq_right_outer_finger" />
    <child link="robotiq_right_inner_finger" />
    <axis xyz="1 0 0" />
    <limit effort="0.12" lower="-0.8757" upper="0.8757" velocity="2" />
    <mimic joint="robotiq_finger_joint" multiplier="1" offset="0" />
  </joint>
  <joint name="robotiq_right_inner_finger_pad_joint" type="fixed">
    <origin rpy="0 0 0" xyz="0 0.0457554015893473 -0.0272203446692936" />
    <parent link="robotiq_right_inner_finger" />
    <child link="robotiq_right_inner_finger_pad" />
    <axis xyz="0 0 1" />
  </joint>
</robot>
